Workbook
Name ExternalData_1: 'Результаты Cucumber'!$B$4:$R$8
Name ExternalData_1: 'Результаты GherkinApprox'!$B$4:$R$8
Name ExternalData_1: 'Результаты Concordialang'!$B$4:$R$8
Name ExternalData_2: 'Результаты Cucumber'!$B$9:$Q$12
Name ExternalData_3: 'Результаты Cucumber'!#REF!
Name ExternalData_2: 'Результаты GherkinApprox'!#REF!
Name ExternalData_3: 'Результаты GherkinApprox'!$B$9:$R$16
Name ExternalData_2: 'Результаты Concordialang'!$B$9:$R$29
Name ExternalData_3: 'Результаты Concordialang'!$B$30:$R$53
Name ExternalData_4: 'Результаты Cucumber'!#REF!
Name ExternalData_5: 'Результаты Cucumber'!$B$9:$R$17
Name ExternalData_6: 'Результаты Cucumber'!$B$18:$R$37
Name ExternalData_4: 'Результаты GherkinApprox'!$B$17:$R$35
Name ExternalData_1: 'Эксперемент по прогреву'!$A$3:$H$29
Name ExternalData_2: 'Эксперемент по прогреву'!$A$45:$I$71
Name ExternalData_3: 'Эксперемент по прогреву'!$A$87:$U$113

Sheet Результаты Cucumber
A1: Метрики производительности Cucumber: 1 - витрина онлайн магазина, 2 - конвертер, 3 - Petclinic
Z3: Среднее время по уровням тестов
A4: № проекта | B4: Название теста | C4: Длительность_среднее | D4: Длительность_дисперсия | E4: Длительность_ДИ_нижн | F4: Длительность_ДИ_верхн | G4: ОЗУ_среднее | H4: ОЗУ_дисперсия | I4: ОЗУ_ДИ_нижн | J4: ОЗУ_ДИ_верхн | K4: CPU_User_среднее_% | L4: CPU_User_дисперсия | M4: CPU_User_ДИ_нижн_% | N4: CPU_User_ДИ_верхн_% | O4: CPU_System_среднее_% | P4: CPU_System_дисперсия | Q4: CPU_System_ДИ_нижн_% | R4: CPU_System_ДИ_верхн_% | V4: Название теста | W4: Длительность_среднее | X4: Уровень сложности | Z4: Уровень | AA4: Среднее по тестам
A5: 1 | B5: Login with different users | C5: 3142.4 | D5: 86353.917 | E5: 3027.2067 | F5: 3257.5933 | G5: 75.173659 | H5: 0.020988152 | I5: 75.116869 | J5: 75.230449 | K5: 8.1737532 | L5: 4.8222764 | M5: 7.3129337 | N5: 9.0345727 | O5: 1.0476926 | P5: 0.57505815 | Q5: 0.75042886 | R5: 1.3449564 | V5: Login with different users | W5: 3142.4 | X5: 2 | Z5: 1 | AA5: =AVERAGEIF($X$5:$X$36,1,W5:W36) -> 633.65
B6: Authorized user checks total item price | C6: 1464.28 | D6: 12034.543 | E6: 1421.2768 | F6: 1507.2832 | G6: 89.114302 | H6: 0.020028304 | I6: 89.058825 | J6: 89.169778 | K6: 10.530333 | L6: 8.0836929 | M6: 9.4158049 | N6: 11.644861 | O6: 0.6903192 | P6: 0.67356441 | Q6: 0.368601 | R6: 1.0120374 | V6: Authorized user checks total item price | W6: 1464.28 | X6: 3 | Z6: 2 | AA6: =AVERAGEIF($X$5:$X$36,2,$W$5:$W$36) -> 828.572
B7: Add 10 different items to the cart | C7: 1638.16 | D7: 41502.89 | E7: 1558.3007 | F7: 1718.0193 | G7: 89.991291 | H7: 0.01969576 | I7: 89.936277 | J7: 90.046305 | K7: 9.6279028 | L7: 11.788408 | M7: 8.2820002 | N7: 10.973805 | O7: 0.97270674 | P7: 0.99971579 | Q7: 0.58076244 | R7: 1.364651 | V7: Add 10 different items to the cart | W7: 1638.16 | X7: 3 | Z7: 3 | AA7: =AVERAGEIF($X$5:$X$36,3,$W$5:$W$36) -> 1086.0429
B8: Итогово: | C8: 6244.84 | D8: 180629.72 | E8: 6078.2378 | F8: 6411.4422 | G8: 80.703315 | H8: 0.019405546 | I8: 80.648708 | J8: 80.757922 | K8: 9.4439963 | L8: 3.3102851 | M8: 8.7307841 | N8: 10.157209 | O8: 1.2588717 | P8: 0.31129721 | Q8: 1.0401592 | R8: 1.4775843 | V8: Итогово: | W8: 6244.84 | X8: 0 | Z8: 4 | AA8: =AVERAGEIF($X$5:$X$36,4,$W$5:$W$36) -> 1470.74
A9: 2 | B9: Конвертация длины | C9: 2210.76 | D9: 33230.107 | E9: 2139.3018 | F9: 2282.2182 | G9: 94.689117 | H9: 12.515103 | I9: 93.302351 | J9: 96.075884 | K9: 19.484756 | L9: 57.7356 | M9: 16.506185 | N9: 22.463327 | O9: 3.8323553 | P9: 5.9964107 | Q9: 2.8724426 | R9: 4.7922681 | V9: Конвертация длины | W9: 2210.76 | X9: 3
B10: Конвертация массы | C10: 1136.24 | D10: 10366.023 | E10: 1096.329 | F10: 1176.151 | G10: 70.55697 | H10: 19.938485 | I10: 68.806591 | J10: 72.307349 | K10: 11.382609 | L10: 11.808337 | M10: 10.035569 | N10: 12.729649 | O10: 1.1329009 | P10: 1.9850145 | Q10: 0.58060997 | R10: 1.6851918 | V10: Конвертация массы | W10: 1136.24 | X10: 2
B11: Конвертация температуры | C11: 1324.56 | D11: 6211.2567 | E11: 1293.6659 | F11: 1355.4541 | G11: 86.44824 | H11: 44.929909 | I11: 83.820673 | J11: 89.075807 | K11: 14.474285 | L11: 42.139777 | M11: 11.929611 | N11: 17.01896 | O11: 2.2276914 | P11: 4.1106269 | Q11: 1.4329239 | R11: 3.0224589 | V11: Конвертация температуры | W11: 1324.56 | X11: 4
B12: Несколько конвертаций | C12: 627.92 | D12: 632.91 | E12: 618.05818 | F12: 637.78182 | G12: 74.42449 | H12: 186.60955 | I12: 69.06957 | J12: 79.779411 | K12: 14.261662 | L12: 42.944409 | M12: 11.692808 | N12: 16.830515 | O12: 1.9022261 | P12: 4.7284989 | Q12: 1.0498178 | R12: 2.7546345 | V12: Несколько конвертаций | W12: 627.92 | X12: 3
B13: Очистка истории | C13: 970.68 | D13: 1369.81 | E13: 956.17171 | F13: 985.18829 | G13: 73.568677 | H13: 138.5667 | I13: 68.954274 | J13: 78.18308 | K13: 6.2694949 | L13: 23.014401 | M13: 4.3889404 | N13: 8.1500493 | O13: 0.76857036 | P13: 1.3104156 | Q13: 0.31983468 | R13: 1.217306 | V13: Очистка истории | W13: 970.68 | X13: 3
B14: Ошибка не попадает в историю | C14: 447.52 | D14: 6503.4267 | E14: 415.90762 | F14: 479.13238 | G14: 70.457576 | H14: 85.144646 | I14: 66.840441 | J14: 74.074711 | K14: 9.4182874 | L14: 41.16937 | M14: 6.9030836 | N14: 11.933491 | O14: 1.0288599 | P14: 3.9992604 | Q14: 0.24493238 | R14: 1.8127874 | V14: Ошибка не попадает в историю | W14: 447.52 | X14: 2
B15: Проверка ошибок ввода | C15: 3111.8 | D15: 36609.333 | E15: 3036.7964 | F15: 3186.8036 | G15: 98.330477 | H15: 3.1282509 | I15: 97.637152 | J15: 99.023802 | K15: 22.871292 | L15: 122.34476 | M15: 18.535397 | N15: 27.207187 | O15: 4.361175 | P15: 1.9791737 | Q15: 3.8096972 | R15: 4.9126527 | V15: Проверка ошибок ввода | W15: 3111.8 | X15: 3
B16: Результат добавляется в историю | C16: 435.84 | D16: 1612.39 | E16: 420.09941 | F16: 451.58059 | G16: 70.77713 | H16: 128.76029 | I16: 66.329004 | J16: 75.225255 | K16: 9.9490083 | L16: 56.226363 | M16: 7.0096261 | N16: 12.888391 | O16: 1.7480863 | P16: 5.8444232 | Q16: 0.80041685 | R16: 2.6957558 | V16: Результат добавляется в историю | W16: 435.84 | X16: 2
B17: Итогово: | C17: 10265.32 | D17: 78280.143 | E17: 10155.644 | F17: 10374.996 | G17: 81.229871 | H17: 9.0826461 | I17: 80.048484 | J17: 82.411259 | K17: 13.950811 | L17: 5.1641297 | M17: 13.060002 | N17: 14.84162 | O17: 3.7466792 | P17: 0.48281321 | Q17: 3.474299 | R17: 4.0190595 | V17: Итогово: | W17: 10265.32 | X17: 0
A18: 3 | B18: Add a new pet to existing owner | C18: 567.96 | D18: 2340.9567 | E18: 548.99369 | F18: 586.92631 | G18: 86.358437 | H18: 88.965266 | I18: 82.661039 | J18: 90.055836 | K18: 12.693593 | L18: 49.084651 | M18: 9.9472234 | N18: 15.439962 | O18: 0.81530193 | P18: 2.5607986 | Q18: 0.18800411 | R18: 1.4425998 | V18: Add a new pet to existing owner | W18: 567.96 | X18: 3
B19: Add a visit to a pet | C19: 616.56 | D19: 14403.257 | E19: 569.51468 | F19: 663.60532 | G19: 69.476974 | H19: 21.473524 | I19: 67.660464 | J19: 71.293484 | K19: 11.018978 | L19: 47.079652 | M19: 8.3292854 | N19: 13.708671 | O19: 0.57801501 | P19: 1.1310755 | Q19: 0.16111504 | R19: 0.99491499 | V19: Add a visit to a pet | W19: 616.56 | X19: 3
B20: Add multiple visits | C20: 993.08 | D20: 40082.577 | E20: 914.59912 | F20: 1071.5609 | G20: 73.404624 | H20: 79.340764 | I20: 69.912946 | J20: 76.896303 | K20: 16.510884 | L20: 56.692568 | M20: 13.559341 | N20: 19.462427 | O20: 1.3028469 | P20: 2.5360137 | Q20: 0.67859213 | R20: 1.9271017 | V20: Add multiple visits | W20: 993.08 | X20: 3
B21: Birth date in future is rejected | C21: 569.04 | D21: 88773.207 | E21: 452.24426 | F21: 685.83574 | G21: 78.283965 | H21: 78.795307 | I21: 74.80431 | J21: 81.763621 | K21: 11.590944 | L21: 112.27946 | M21: 7.4372338 | N21: 15.744655 | O21: 0.99067055 | P21: 2.1843551 | Q21: 0.41131164 | R21: 1.5700294 | V21: Birth date in future is rejected | W21: 569.04 | X21: 3
B22: Create new owner - valid | C22: 619.04 | D22: 18802.29 | E22: 565.28839 | F22: 672.79161 | G22: 74.924673 | H22: 10.957431 | I22: 73.627075 | J22: 76.222272 | K22: 21.889415 | L22: 79.0598 | M22: 18.403924 | N22: 25.374906 | O22: 1.7056279 | P22: 2.4127499 | Q22: 1.0967332 | R22: 2.3145227 | V22: Create new owner - valid | W22: 619.04 | X22: 3
B23: Duplicate pet name validation | C23: 704.24 | D23: 1086438.2 | E23: 295.6492 | F23: 1112.8308 | G23: 76.428587 | H23: 55.308875 | I23: 73.513286 | J23: 79.343889 | K23: 7.3453425 | L23: 42.121872 | M23: 4.801209 | N23: 9.889476 | O23: 0.40458781 | P23: 2.2404306 | Q23: -0.18216046 | R23: 0.99133608 | V23: Duplicate pet name validation | W23: 704.24 | X23: 3
B24: Edit owner address successfully | C24: 560.48 | D24: 4408.01 | E24: 534.454 | F24: 586.506 | G24: 79.412335 | H24: 104.32807 | I24: 75.408404 | J24: 83.416267 | K24: 9.438408 | L24: 19.444687 | M24: 7.7098397 | N24: 11.166976 | O24: 0.90841111 | P24: 1.8808637 | Q24: 0.37080433 | R24: 1.4460179 | V24: Edit owner address successfully | W24: 560.48 | X24: 3
B25: Edit pet name successfully | C25: 531.28 | D25: 2165.5433 | E25: 513.03812 | F25: 549.52188 | G25: 80.686241 | H25: 203.37007 | I25: 75.096012 | J25: 86.276469 | K25: 8.8889355 | L25: 47.092691 | M25: 6.1988702 | N25: 11.579001 | O25: 0.57302245 | P25: 1.3970747 | Q25: 0.10968662 | R25: 1.0363583 | V25: Edit pet name successfully | W25: 531.28 | X25: 2
B26: Find owners – no results | C26: 498.84 | D26: 2581.64 | E26: 478.92254 | F26: 518.75746 | G26: 85.623166 | H26: 31.240349 | I26: 83.432158 | J26: 87.814174 | K26: 20.422862 | L26: 250.47256 | M26: 14.218942 | N26: 26.626781 | O26: 1.550445 | P26: 9.8079134 | Q26: 0.32279552 | R26: 2.7780944 | V26: Find owners – no results | W26: 498.84 | X26: 2
B27: Find owners by last name – multiple results | C27: 508.32 | D27: 2307.8933 | E27: 489.48811 | F27: 527.15189 | G27: 77.976555 | H27: 22.868677 | I27: 76.101964 | J27: 79.851146 | K27: 8.1725959 | L27: 26.414452 | M27: 6.1579122 | N27: 10.18728 | O27: 1.0846613 | P27: 2.1968596 | Q27: 0.50364646 | R27: 1.6656761 | V27: Find owners by last name – multiple results | W27: 508.32 | X27: 2
B28: Find owners by last name - single result | C28: 534.96 | D28: 2116.1233 | E28: 516.92747 | F28: 552.99253 | G28: 82.798575 | H28: 30.333594 | I28: 80.639599 | J28: 84.957552 | K28: 11.258609 | L28: 39.076181 | M28: 8.8081796 | N28: 13.709038 | O28: 0.95891753 | P28: 3.482055 | Q28: 0.22743512 | R28: 1.6903999 | V28: Find owners by last name - single result | W28: 534.96 | X28: 2
B29: Non-existent owner | C29: 651.56 | D29: 1058500.1 | E29: 248.25694 | F29: 1054.8631 | G29: 68.084329 | H29: 24.734976 | I29: 66.134746 | J29: 70.033913 | K29: 8.5496229 | L29: 20.525677 | M29: 6.7736562 | N29: 10.32559 | O29: 0.79405165 | P29: 3.9447483 | Q29: 0.015485146 | R29: 1.5726182 | V29: Non-existent owner | W29: 651.56 | X29: 1
B30: Telephone validation with incorrect formats | C30: 1616.92 | D30: 10841.577 | E30: 1576.1038 | F30: 1657.7362 | G30: 86.857256 | H30: 33.136651 | I30: 84.60073 | J30: 89.113783 | K30: 13.790228 | L30: 41.988828 | M30: 11.250116 | N30: 16.330341 | O30: 2.3753843 | P30: 5.1190828 | Q30: 1.488469 | R30: 3.2622996 | V30: Telephone validation with incorrect formats | W30: 1616.92 | X30: 4
... B36: Visit with empty description shows error | C36: 514.4 | D36: 6196.0833 | E36: 483.54364 | F36: 545.25636 | G36: 71.339175 | H36: 39.160547 | I36: 68.886102 | J36: 73.792248 | K36: 5.2030565 | L36: 12.750065 | M36: 3.803333 | N36: 6.6027801 | O36: 0.75137689 | P36: 2.7961666 | Q36: 0.095884596 | R36: 1.4068692 | V36: Visit with empty description shows error | W36: 514.4 | X36: 1
B37: Итогово: | C37: 12456.24 | D37: 2925610.8 | E37: 11785.747 | F37: 13126.733 | G37: 78.076555 | H37: 18.825798 | I37: 76.375717 | J37: 79.777392 | K37: 11.511351 | L37: 1.9293988 | M37: 10.966852 | N37: 12.05585 | O37: 3.166562 | P37: 0.82742878 | Q37: 2.8099866 | R37: 3.5231374 | V37: Итогово: | W37: 12456.24
A40: № проекта | B40: Название теста | C40: Длительность_ДИ | D40: ОЗУ_ДИ | E40: CPU_User_ДИ | F40: СPU_System_ДИ | J40: Среднее по всем проектам
A41: 1 | B41: Standard user logs in | C41: =C5-E5 -> 115.19326 | D41: =G5-I5 -> 0.05679017 | E41: =K5-M5 -> 0.86081954 | F41: =O5-Q5 -> 0.29726375 | J41: длительность | K41: =AVERAGE(C8,C17,C37) -> 9655.4667
B42: Authorized user checks total item price | C42: =C6-E6 -> 43.00321 | D42: =G6-I6 -> 0.055476385 | E42: =K6-M6 -> 1.114528 | F42: =O6-Q6 -> 0.3217182 | J42: Дисперсия_дл | K42: =VARP(C8,C17,C37) -> 6616208.9
B43: Add 5 different items to the cart | C43: =C7-E7 -> 79.859252 | D43: =G7-I7 -> 0.055013901 | E43: =K7-M7 -> 1.3459027 | F43: =O7-Q7 -> 0.39194429 | J43: ДИ_дл | K43: =SQRT(K42)/SQRT(3)*3.182 -> 4725.4607
B44: Итогово: | C44: =C8-E8 -> 166.60218 | D44: =G8-I8 -> 0.054607086 | E44: =K8-M8 -> 0.71321221 | F44: =O8-Q8 -> 0.21871254 | J44: ОЗУ | K44: =AVERAGE(G8,G17,G37) -> 80.003247
A45: 2 | B45: Конвертация длины | C45: =C9-E9 -> 71.458177 | D45: =G9-I9 -> 1.3867663 | E45: =K9-M9 -> 2.9785707 | F45: =O9-Q9 -> 0.95991273 | J45: ОЗУ_дл | K45: =VARP(G8,G17,G37) -> 1.9022823
B46: Конвертация массы | C46: =C10-E10 -> 39.910959 | D46: =G10-I10 -> 1.7503792 | E46: =K10-M10 -> 1.3470398 | F46: =O10-Q10 -> 0.55229093 | J46: ДИ_ОЗУ | K46: =SQRT(K45)/SQRT(3)*3.182 -> 2.5338274
B47: Конвертация температуры | C47: =C11-E11 -> 30.894118 | D47: =G11-I11 -> 2.6275672 | E47: =K11-M11 -> 2.5446742 | F47: =O11-Q11 -> 0.7947675 | J47: CPU_User | K47: =AVERAGE(K8,K17,K37) -> 11.635386
B48: Несколько конвертаций | C48: =C12-E12 -> 9.8618194 | D48: =G12-I12 -> 5.3549202 | E48: =K12-M12 -> 2.5688538 | F48: =O12-Q12 -> 0.85240839 | J48: Дисперсия_CPU_User | K48: =VARP(K8,K17,K37) -> 3.3929217
...

Sheet Результаты GherkinApprox
A1: Метрики производительности GherkinApprox: 1 - витрина онлайн магазина, 2 - конвертер, 3 - Petclinic
Z3: Среднее время по уровням тестов
B4: Название теста | C4: Длительность_среднее | D4: Длительность_дисперсия | E4: Длительность_ДИ_нижн | F4: Длительность_ДИ_верхн | G4: ОЗУ_среднее | H4: ОЗУ_дисперсия | I4: ОЗУ_ДИ_нижн | J4: ОЗУ_ДИ_верхн | K4: CPU_User_среднее_% | L4: CPU_User_дисперсия | M4: CPU_User_ДИ_нижн_% | N4: CPU_User_ДИ_верхн_% | O4: CPU_System_среднее_% | P4: CPU_System_дисперсия | Q4: CPU_System_ДИ_нижн_% | R4: CPU_System_ДИ_верхн_% | V4: Название теста | W4: Длительность_среднее | X4: Уровень сложности | Z4: Уровень | AA4: Среднее по тестам
A5: 1 | B5: Авторизация разных пользователей | C5: 2196.88 | D5: 114630.19 | E5: 2064.1602 | F5: 2329.5998 | G5: 29.5828 | H5: 0.643896 | I5: 29.268247 | J5: 29.897353 | K5: 11.9168 | L5: 9.3108393 | M5: 10.720664 | N5: 13.112936 | O5: 8.3324 | P5: 1.7618857 | Q5: 7.8120747 | R5: 8.8527253 | V5: Авторизация разных пользователей | W5: 2196.88 | X5: 2 | Z5: 1 | AA5: =AVERAGEIF($X$5:$X$34,1,W5:W34) -> 262.24
B6: Проверка добавления товара и запоминание его цены при авторизации | C6: 725.56 | D6: 23261.673 | E6: 665.77303 | F6: 785.34697 | G6: 30.4596 | H6: 0.63488733 | I6: 30.147255 | J6: 30.771945 | K6: 17.0204 | L6: 30.735204 | M6: 14.847178 | N6: 19.193622 | O6: 1.566 | P6: 4.458375 | Q6: 0.73829731 | R6: 2.3937027 | V6: Проверка добавления товара и запоминание его цены при авторизации | W6: 725.56 | X6: 3 | Z6: 2 | AA6: =AVERAGEIF($X$5:$X$34,2,$W$5:$W$34) -> 850.625
B7: Массовое добавление товаров в корзину | C7: 940 | D7: 79083.583 | E7: 829.76253 | F7: 1050.2375 | G7: 35.0868 | H7: 8.3790227 | I7: 33.952096 | J7: 36.221504 | K7: 14.4184 | L7: 25.531689 | M7: 12.437667 | N7: 16.399133 | O7: 1.0952 | P7: 1.6464093 | Q7: 0.59221507 | R7: 1.5981849 | V7: Массовое добавление товаров в корзину | W7: 940 | X7: 3 | Z7: 3 | AA7: =AVERAGEIF($X$5:$X$34,3,$W$5:$W$34) -> 765.80615
B8: Итогово: | C8: 3862.44 | D8: 218781.51 | E8: 3679.0856 | F8: 4045.7944 | G8: 31.709733 | H8: 0.60435919 | I8: 31.40499 | J8: 32.014476 | K8: 14.451867 | L8: 3.9028112 | M8: 13.67745 | N8: 15.226284 | O8: 3.6645333 | P8: 0.88654248 | Q8: 3.2954403 | R8: 4.0336264 | V8: Итогово: | W8: 3862.44 | X8: 0 | Z8: 4 | AA8: =AVERAGEIF($X$5:$X$34,4,$W$5:$W$34) -> 822.33333
B9: Килограммы в граммы | C9: 2460.36 | D9: ='Эксперемент по прогреву'!B34 -> 2083374.3 | E9: =C9-SQRT(D9)/5*1.96 -> 1894.5512 | F9: =C9-SQRT(D9)/5*1.96 -> 1894.5512 | G9: 24.3336 | H9: 0.44481567 | I9: 24.072158 | J9: 24.595042 | K9: 8.1664 | L9: 7.423949 | M9: 7.0983206 | N9: 9.2344794 | O9: 7.926 | P9: 2.7673833 | Q9: 7.2738902 | R9: 8.5781098 | V9: Килограммы в граммы | W9: 2460.36 | X9: 2
B10: Конвертация длины (5) | C10: 1328.4 | D10: ='Эксперемент по прогреву'!C34 -> 22858.96 | E10: =C10-SQRT(D10)/5*1.96 -> 1269.1328 | F10: =C10-SQRT(D10)/5*1.96 -> 1269.1328 | G10: 35.086 | H10: 1.16855 | I10: 34.66225 | J10: 35.50975 | K10: 25.17 | L10: 44.775458 | M10: 22.546953 | N10: 27.793047 | O10: 1.862 | P10: 1.5200833 | Q10: 1.3786967 | R10: 2.3453033 | V10: Конвертация длины (5) | W10: 1328.4 | X10: 3
B11: Конвертация температуры с проверкой значений | C11: 891.32 | D11: ='Эксперемент по прогреву'!D34 -> 31421.258 | E11: =C11-SQRT(D11)/5*1.96 -> 821.83391 | F11: =C11-SQRT(D11)/5*1.96 -> 821.83391 | G11: 35.8004 | H11: 1.1705707 | I11: 35.376284 | J11: 36.224516 | K11: 12.5736 | L11: 16.291941 | M11: 10.99136 | N11: 14.15584 | O11: 1.0488 | P11: 1.0765943 | Q11: 0.64206447 | R11: 1.4555355 | V11: Конвертация температуры с проверкой значений | W11: 891.32 | X11: 4
B12: Проверка ошибок ввода | C12: 1301.92 | D12: ='Эксперемент по прогреву'!E34 -> 31825.594 | E12: =C12-SQRT(D12)/5*1.96 -> 1231.9883 | F12: =C12-SQRT(D12)/5*1.96 -> 1231.9883 | G12: 32.188 | H12: 1.2123083 | I12: 31.756389 | J12: 32.619611 | K12: 17.7964 | L12: 15.301866 | M12: 16.26299 | N12: 19.32981 | O12: 1.5812 | P12: 2.342561 | Q12: 0.98122726 | R12: 2.1811727 | V12: Проверка ошибок ввода | W12: 1301.92 | X12: 3
B13: Проверка истории при конвертации | C13: 842.52 | D13: ='Эксперемент по прогреву'!F34 -> 6462.4896 | E13: =C13-SQRT(D13)/5*1.96 -> 811.00727 | F13: =C13-SQRT(D13)/5*1.96 -> 811.00727 | G13: 36.0044 | H13: 0.956134 | I13: 35.621094 | J13: 36.387706 | K13: 10.6836 | L13: 16.567449 | M13: 9.0880373 | N13: 12.279163 | O13: 0.8328 | P13: 1.7570377 | Q13: 0.31319107 | R13: 1.3524089 | V13: Проверка истории при конвертации | W13: 842.52 | X13: 4
B14: Несколько конвертаций | C14: 850.48 | D14: ='Эксперемент по прогреву'!G34 -> 467.4496 | E14: =C14-SQRT(D14)/5*1.96 -> 842.00473 | F14: =C14-SQRT(D14)/5*1.96 -> 842.00473 | G14: 36.2448 | H14: 7.4587093 | I14: 35.174223 | J14: 37.315377 | K14: 13.6992 | L14: 19.585883 | M14: 11.964367 | N14: 15.434033 | O14: 1.0184 | P14: 1.3981057 | Q14: 0.55489325 | R14: 1.4819068 | V14: Несколько конвертаций | W14: 850.48 | X14: 3
B15: Очистка истории | C15: 737.92 | D15: ='Эксперемент по прогреву'!H29 -> 710 | E15: =C15-SQRT(D15)/5*1.96 -> 727.47484 | F15: =C15-SQRT(D15)/5*1.96 -> 727.47484 | G15: 38.4996 | H15: 8.190779 | I15: 37.377714 | J15: 39.621486 | K15: 6.1864 | L15: 9.651849 | M15: 4.9685569 | N15: 7.4042431 | O15: 0.3412 | P15: 1.0407693 | Q15: -0.058710964 | R15: 0.74111096 | V15: Очистка истории | W15: 737.92 | X15: 3
B16: Итогово: | C16: 8412.92 | D16: ='Эксперемент по прогреву'!I34 -> 2045994.6 | E16: 7840.6477 | F16: 8985.1923 | G16: 34.0224 | H16: 1.6112874 | I16: 33.524809 | J16: 34.519991 | K16: 13.467943 | L16: 2.4745498 | M16: 12.851299 | N16: 14.084586 | O16: 2.0872 | P16: 0.23332236 | Q16: 1.8978505 | R16: 2.2765495 | V16: Итогово: | W16: 8412.92 | X16: 0
B17: Add a visit to a pet | C17: 1439.24 | D17: 375140.36 | E17: 1199.1451 | F17: 1679.3349 | G17: 27.5696 | H17: 0.15721233 | I17: 27.414172 | J17: 27.725028 | K17: 13.332 | L17: 24.585108 | M17: 11.388332 | N17: 15.275668 | O17: 8.3816 | P17: 2.8916057 | Q17: 7.7150149 | R17: 9.0481851 | V17: Add a visit to a pet | W17: 1439.24 | X17: 3
B18: Visit with empty description shows error | C18: 331.92 | D18: 10598.577 | E18: 291.56384 | F18: 372.27616 | G18: 32.966 | H18: 0.15069167 | I18: 32.813829 | J18: 33.118171 | K18: 13.4092 | L18: 38.693299 | M18: 10.970806 | N18: 15.847594 | O18: 0.5992 | P18: 2.7718743 | Q18: -0.053438719 | R18: 1.2518387 | V18: Visit with empty description shows error | W18: 331.92 | X18: 1
B19: Add multiple visits | C19: 875 | D19: 139670.17 | E19: 728.49991 | F19: 1021.5001 | G19: 34.22 | H19: 0.14323333 | I19: 34.071643 | J19: 34.368357 | K19: 22.1108 | L19: 23.483224 | M19: 20.211188 | N19: 24.010412 | O19: 2.186 | P19: 4.5971833 | Q19: 1.3455111 | R19: 3.0264889 | V19: Add multiple visits | W19: 875 | X19: 3
B20: Trigger exception page | C20: 256.16 | D20: 19411.723 | E20: 201.54422 | F20: 310.77578 | G20: 36.4056 | H20: 0.71686733 | I20: 36.073701 | J20: 36.737499 | K20: 7.8068 | L20: 63.477331 | M20: 4.6836316 | N20: 10.929968 | O20: 1.094 | P20: 6.6644583 | Q20: 0.082028002 | R20: 2.105972 | V20: Trigger exception page | W20: 256.16 | X20: 1
B21: Non-existent owner | C21: 250.08 | D21: 13292.577 | E21: 204.88497 | F21: 295.27503 | G21: 38.6944 | H21: 0.73420067 | I21: 38.358513 | J21: 39.030287 | K21: 7.0848 | L21: 43.122293 | M21: 4.5106314 | N21: 9.6589686 | O21: 1.6816 | P21: 9.3681973 | Q21: 0.48178557 | R21: 2.8814144 | V21: Non-existent owner | W21: 250.08 | X21: 1
B22: Create new owner - valid | C22: 358.04 | D22: 6375.29 | E22: 326.7406 | F22: 389.3394 | G22: 38.966 | H22: 0.73513333 | I22: 38.6299 | J22: 39.3021 | K22: 17.1 | L22: 69.369833 | M22: 13.835089 | N22: 20.364911 | O22: 1.6212 | P22: 9.1804193 | Q22: 0.43347109 | R22: 2.8089289 | V22: Create new owner - valid | W22: 358.04 | X22: 3
B23: Find owners by last name – multiple results | C23: 364.72 | D23: 37514.127 | E23: 288.79523 | F23: 440.64477 | G23: 35.458 | H23: 0.80454167 | I23: 35.106391 | J23: 35.809609 | K23: 13.8156 | L23: 92.405651 | M23: 10.047388 | N23: 17.583812 | O23: 0.7356 | P23: 3.010109 | Q23: 0.055493104 | R23: 1.4157069 | V23: Find owners by last name – multiple results | W23: 364.72 | X23: 2
B24: Find owners by last name - single result | C24: 383.56 | D24: 103275.42 | E24: 257.58494 | F24: 509.53506 | G24: 40.1028 | H24: 1.3565377 | I24: 39.646236 | J24: 40.559364 | K24: 11.4084 | L24: 43.907806 | M24: 8.8108918 | N24: 14.005908 | O24: 0.9172 | P24: 6.2627543 | Q24: -0.06379943 | R24: 1.8981994 | V24: Find owners by last name - single result | W24: 383.56 | X24: 2
B25: Find owners – no results | C25: 369.36 | D25: 85102.907 | E25: 255.00418 | F25: 483.71582 | G25: 38.752 | H25: 14.567525 | I25: 37.255837 | J25: 40.248163 | K25: 14.2056 | L25: 54.293476 | M25: 11.317183 | N25: 17.094017 | O25: 0.7576 | P25: 3.283969 | Q25: 0.047228398 | R25: 1.4679716 | V25: Find owners – no results | W25: 369.36 | X25: 2
B26: Edit owner address successfully | C26: 339.88 | D26: 2528.9433 | E26: 320.16687 | F26: 359.59313 | G26: 35.2616 | H26: 1.2247307 | I26: 34.827783 | J26: 35.695417 | K26: 12.1524 | L26: 65.460694 | M26: 8.9808149 | N26: 15.323985 | O26: 1.0868 | P26: 4.0211643 | Q26: 0.30072863 | R26: 1.8728714 | V26: Edit owner address successfully | W26: 339.88 | X26: 3
B27: Telephone validation with multiple incorrect formats | C27: 733.16 | D27: 29918.14 | E27: 665.3563 | F27: 800.9637 | G27: 36.7604 | H27: 2.9589707 | I27: 36.086095 | J27: 37.434705 | K27: 23.4584 | L27: 47.406164 | M27: 20.759396 | N27: 26.157404 | O27: 1.6832 | P27: 2.694606 | Q27: 1.039722 | R27: 2.326678 | V27: Telephone validation with multiple incorrect formats | W27: 733.16 | X27: 4
B28: Add a new pet to existing owner | C28: 347.92 | D28: 1666.5767 | E28: 331.9171 | F28: 363.9229 | G28: 32.9776 | H28: 10.328736 | I28: 31.717777 | J28: 34.237423 | K28: 10.6684 | L28: 42.782422 | M28: 8.1043957 | N28: 13.232404 | O28: 0.148 | P28: 0.5476 | Q28: -0.14208 | R28: 0.43808 | V28: Add a new pet to existing owner | W28: 347.92 | X28: 3
... B34: View vets as HTML with loop | C34: 210.8 | D34: 3158.0833 | E34: 188.77084 | F34: 232.82916 | G34: 29.0568 | H34: 6.061681 | I34: 28.091677 | J34: 30.021923 | K34: 7.8996 | L34: 49.792637 | M34: 5.1334952 | N34: 10.665705 | O34: 0 | P34: 0 | Q34: 0 | R34: 0 | V34: View vets as HTML with loop | W34: 210.8 | X34: 1
B35: Итогово: | C35: 8001.08 | D35: 5541151.7 | E35: 7078.3257 | F35: 8923.8343 | G35: 35.985711 | H35: 0.090156906 | I35: 35.868009 | J35: 36.103414 | K35: 13.152356 | L35: 5.2357952 | M35: 12.255387 | N35: 14.049324 | O35: 1.5063778 | P35: 0.26754625 | Q35: 1.3036163 | R35: 1.7091393 | V35: Итогово: | W35: 8001.08
A37: № проекта
A38: 1 | B38: Название теста | C38: Длительность_ДИ | D38: ОЗУ_ДИ | E38: CPU_User_ДИ | F38: СPU_System_ДИ | J38: Среднее по всем проектам
B39: Авторизация разных пользователей | C39: =C5-E5 -> 132.71976 | D39: =G5-I5 -> 0.31455307 | E39: =K5-M5 -> 1.1961358 | F39: =O5-Q5 -> 0.52032528 | J39: длительность | K39: =AVERAGE(C8,C16,C35) -> 6758.8133
B40: Проверка добавления товара и запоминание его цены при авторизации | C40: =C6-E6 -> 59.78697 | D40: =G6-I6 -> 0.31234489 | E40: =K6-M6 -> 2.1732221 | F40: =O6-Q6 -> 0.82770269 | J40: Дисперсия_дл | K40: =VARP(C8,C16,C35) -> 4222757.9
B41: Массовое добавление товаров в корзину | C41: =C7-E7 -> 110.23747 | D41: =G7-I7 -> 1.1347044 | E41: =K7-M7 -> 1.9807326 | F41: =O7-Q7 -> 0.50298493 | J41: ДИ_дл | K41: =SQRT(K40)/SQRT(3)*3.182 -> 3775.1798
A42: 2 | B42: Итогово: | C42: =C8-E8 -> 183.35441 | D42: =G8-I8 -> 0.30474292 | E42: =K8-M8 -> 0.77441693 | F42: =O8-Q8 -> 0.36909303 | J42: ОЗУ | K42: =AVERAGE(G8,G16,G35) -> 33.905948
B43: Килограммы в граммы | C43: =C9-E9 -> 565.80883 | D43: =G9-I9 -> 0.26144245 | E43: =K9-M9 -> 1.0680794 | F43: =O9-Q9 -> 0.6521098 | J43: ОЗУ_дл | K43: =VARP(G8,G16,G35) -> 3.0541115
B44: Конвертация длины (5) | C44: =C10-E10 -> 59.267185 | D44: =G10-I10 -> 0.42375001 | E44: =K10-M10 -> 2.6230471 | F44: =O10-Q10 -> 0.48330331 | J44: ДИ_ОЗУ | K44: =SQRT(K43)/SQRT(3)*3.182 -> 3.2105689
B45: Конвертация температуры с проверкой значений | C45: =C11-E11 -> 69.486086 | D45: =G11-I11 -> 0.42411622 | E45: =K11-M11 -> 1.5822404 | F45: =O11-Q11 -> 0.40673553 | J45: CPU_User | K45: =AVERAGE(K8,K16,K35) -> 13.690722
B46: Проверка ошибок ввода | C46: =C12-E12 -> 69.931738 | D46: =G12-I12 -> 0.43161111 | E46: =K12-M12 -> 1.5334099 | F46: =O12-Q12 -> 0.59997274 | J46: Дисперсия_CPU_User | K46: =VARP(K8,K16,K35) -> 0.30627006
B47: Проверка истории при конвертации | C47: =C13-E13 -> 31.512728 | D47: =G13-I13 -> 0.38330585 | E47: =K13-M13 -> 1.5955627 | F47: =O13-Q13 -> 0.51960893 | J47: ДИ_CPU_User | K47: =SQRT(K46)/SQRT(3)*3.182 -> 1.0166976
...

Sheet Результаты Concordialang
A1: Метрики производительности Concordialang: 1 - витрина онлайн магазина, 2 - конвертер, 3 - Petclinic
Z3: Среднее время по уровням тестов
A4: № проекта | B4: Название теста | C4: Длительность_среднее | D4: Длительность_дисперсия | E4: Длительность_ДИ_нижн | F4: Длительность_ДИ_верхн | G4: ОЗУ_среднее | H4: ОЗУ_дисперсия | I4: ОЗУ_ДИ_нижн | J4: ОЗУ_ДИ_верхн | K4: CPU_User_среднее_% | L4: CPU_User_дисперсия | M4: CPU_User_ДИ_нижн_% | N4: CPU_User_ДИ_верхн_% | O4: CPU_System_среднее_% | P4: CPU_System_дисперсия | Q4: CPU_System_ДИ_нижн_% | R4: CPU_System_ДИ_верхн_% | V4: Название теста | W4: Длительность_среднее | X4: Уровень сложности | Z4: Уровень | AA4: Среднее по тестам
A5: 1 | B5: Login with different users | standard_user_login - 1 | C5: 1731.08 | D5: 81955.91 | E5: 1618.8585 | F5: 1843.3015 | G5: 631.32797 | H5: 369.60259 | I5: 623.79175 | J5: 638.86419 | K5: 386.7532 | L5: 3477.4954 | M5: 363.63685 | N5: 409.86955 | O5: 114.5984 | P5: 6900.0827 | Q5: 82.036239 | R5: 147.16056 | V5: Login with different users | standard_user_login - 1 | W5: 1731.08 | X5: 2 | Z5: 1 | AA5: =AVERAGEIF($X$5:$X$52,1,W5:W52) -> 601.672
B6: Authorized user checks total item price | check_two_items - 1 | C6: 1866.92 | D6: 16384.41 | E6: 1816.7434 | F6: 1917.0966 | G6: 627.92875 | H6: 88.882122 | I6: 624.23308 | J6: 631.62442 | K6: 356.322 | L6: 904.06323 | M6: 344.53548 | N6: 368.10852 | O6: 149.022 | P6: 5625.3453 | Q6: 119.6211 | R6: 178.4229 | V6: Authorized user checks total item price | check_two_items - 1 | W6: 1866.92 | X6: 3 | Z6: 2 | AA6: =AVERAGEIF($X$5:$X$52,2,$W$5:$W$52) -> 2192.816
B7: Add 10 different items to the cart | add_five_items - 1 | C7: 2394.64 | D7: 53193.74 | E7: 2304.23 | F7: 2485.05 | G7: 629.025 | H7: 141.92079 | I7: 624.35508 | J7: 633.69492 | K7: 281.6972 | L7: 725.51505 | M7: 271.13853 | N7: 292.25587 | O7: 127.864 | P7: 3402.5812 | Q7: 104.99799 | R7: 150.73001 | V7: Add 10 different items to the cart | add_five_items - 1 | W7: 2394.64 | X7: 3 | Z7: 3 | AA7: =AVERAGEIF($X$5:$X$52,3,$W$5:$W$52) -> 3825.3414
B8: Итогово | C8: 5992.64 | D8: 130880.91 | E8: 5850.8243 | F8: 6134.4557 | G8: 629.42724 | H8: 74.708057 | I8: 626.03903 | J8: 632.81545 | K8: 341.5912 | L8: 549.66596 | M8: 332.40078 | N8: 350.78162 | O8: 130.4948 | P8: 1673.6847 | Q8: 114.45781 | R8: 146.53179 | V8: Итогово | W8: 5992.64 | X8: 0 | Z8: 4 | AA8: =AVERAGEIF($X$5:$X$52,4,$W$5:$W$52) -> 5531.2
A9: 2 | B9: Kilograms to grams | kilograms_to_grams - 1 | C9: 5550.8 | D9: 45.083333 | E9: 5548.168 | F9: 5553.432 | G9: 550.42953 | H9: 3.0871995 | I9: 549.74077 | J9: 551.11829 | K9: 89.6648 | L9: 32.323309 | M9: 87.436139 | N9: 91.893461 | O9: 88.1108 | P9: 68.605624 | Q9: 84.863922 | R9: 91.357678 | V9: Kilograms to grams | kilograms_to_grams - 1 | W9: 5550.8 | X9: 2
B10: Meters to kilometers | meters_to_kilometers - 1 | C10: 5559.56 | D10: 69.506667 | E10: 5556.2919 | F10: 5562.8281 | G10: 557.88031 | H10: 1643.0157 | I10: 541.99093 | J10: 573.76969 | K10: 338.1352 | L10: 1545570 | M10: -149.20295 | N10: 825.47335 | O10: 87.5372 | P10: 29.699513 | Q10: 85.400907 | R10: 89.673493 | V10: Meters to kilometers | meters_to_kilometers - 1 | W10: 5559.56 | X10: 3
B11: Kilometers to meters | kilometers_to_meters - 1 | C11: 5520.68 | D11: 55.56 | E11: 5517.7581 | F11: 5523.6019 | G11: 549.34016 | H11: 1.9536501 | I11: 548.79225 | J11: 549.88807 | K11: 91.4416 | L11: 56.239206 | M11: 88.501882 | N11: 94.381318 | O11: 90.016 | P11: 29.968792 | Q11: 87.870045 | R11: 92.161955 | V11: Kilometers to meters | kilometers_to_meters - 1 | W11: 5520.68 | X11: 3
B12: Meters to centimeters | meters_to_centimeters - 1 | C12: 5520.96 | D12: 39.456667 | E12: 5518.4977 | F12: 5523.4223 | G12: 550.19047 | H12: 1.929679 | I12: 549.64593 | J12: 550.73501 | K12: 92.1632 | L12: 33.517606 | M12: 89.89374 | N12: 94.43266 | O12: 89.4556 | P12: 53.214392 | Q12: 86.596031 | R12: 92.315169 | V12: Meters to centimeters | meters_to_centimeters - 1 | W12: 5520.96 | X12: 3
B13: Centimeters to meters | centimeters_to_meters - 1 | C13: 5543.16 | D13: 85.806667 | E13: 5539.5288 | F13: 5546.7912 | G13: 631.87766 | H13: 166737.12 | I13: 471.81051 | J13: 791.94481 | K13: 3271.6868 | L13: 2.5313465e+08 | M13: -2965.1139 | N13: 9508.4875 | O13: 87.2756 | P13: 59.155792 | Q13: 84.260618 | R13: 90.290582 | V13: Centimeters to meters | centimeters_to_meters - 1 | W13: 5543.16 | X13: 3
B14: Meters to millimeters | meters_to_millimeters - 1 | C14: 5518.44 | D14: 65.34 | E14: 5515.2713 | F14: 5521.6087 | G14: 549.86406 | H14: 2.6182289 | I14: 549.22977 | J14: 550.49836 | K14: 91.2892 | L14: 29.852849 | M14: 89.1474 | N14: 93.431 | O14: 85.7836 | P14: 67.169549 | Q14: 82.570884 | R14: 88.996316 | V14: Meters to millimeters | meters_to_millimeters - 1 | W14: 5518.44 | X14: 3
B15: Celsius to Fahrenheit | celsius_to_fahrenheit - 1 | C15: 5542 | D15: 86.583333 | E15: 5538.3524 | F15: 5545.6476 | G15: 549.75141 | H15: 3.8707388 | I15: 548.98018 | J15: 550.52263 | K15: 91.9764 | L15: 53.026191 | M15: 89.121892 | N15: 94.830908 | O15: 86.3524 | P15: 99.858619 | Q15: 82.435172 | R15: 90.269628 | V15: Celsius to Fahrenheit | celsius_to_fahrenheit - 1 | W15: 5542 | X15: 4
B16: Fahrenheit to Celsius | fahrenheit_to_celsius - 1 | C16: 5532.36 | D16: 90.823333 | E16: 5528.6242 | F16: 5536.0958 | G16: 629.18391 | H16: 156231.38 | I16: 474.24153 | J16: 784.12628 | K16: 2300.358 | L16: 1.219841e+08 | M16: -2029.1415 | N16: 6629.8575 | O16: 1031.6568 | P16: 22187907 | Q16: -814.82163 | R16: 2878.1352 | V16: Fahrenheit to Celsius | fahrenheit_to_celsius - 1 | W16: 5532.36 | X16: 4
B17: Kelvin to Celsius | kelvin_to_celsius - 1 | C17: 5519.24 | D17: 41.356667 | E17: 5516.7191 | F17: 5521.7609 | G17: 549.71453 | H17: 2.4389368 | I17: 549.10234 | J17: 550.32672 | K17: 90.7428 | L17: 35.146846 | M17: 88.418837 | N17: 93.066763 | O17: 87.9892 | P17: 58.687041 | Q17: 84.986187 | R17: 90.992213 | V17: Kelvin to Celsius | kelvin_to_celsius - 1 | W17: 5519.24 | X17: 4
B18: Non-numeric value | alphabetic_string - 1 | C18: 5558.08 | D18: 60.91 | E18: 5555.0206 | F18: 5561.1394 | G18: 550.12953 | H18: 2.0973825 | I18: 549.56182 | J18: 550.69724 | K18: 88.164 | L18: 37.925008 | M18: 85.749935 | N18: 90.578065 | O18: 87.8704 | P18: 60.573312 | Q18: 84.819509 | R18: 90.921291 | V18: Non-numeric value | alphabetic_string - 1 | W18: 5558.08 | X18: 3
B19: Symbols | symbols - 1 | C19: 5556 | D19: 56 | E19: 5553.0665 | F19: 5558.9335 | G19: 549.71563 | H19: 2.3085938 | I19: 549.12002 | J19: 550.31123 | K19: 91.8268 | L19: 52.763181 | M19: 88.97938 | N19: 94.67422 | O19: 88.4388 | P19: 114.61331 | Q19: 84.242142 | R19: 92.635458 | V19: Symbols | symbols - 1 | W19: 5556 | X19: 3
B20: Negative mass | negative_mass - 1 | C20: 5542.24 | D20: 48.773333 | E20: 5539.5024 | F20: 5544.9776 | G20: 549.79344 | H20: 1.8507885 | I20: 549.26015 | J20: 550.32673 | K20: 90.1172 | L20: 71.558754 | M20: 86.801178 | N20: 93.433222 | O20: 87.9436 | P20: 153.36061 | Q20: 83.089117 | R20: 92.798083 | V20: Negative mass | negative_mass - 1 | W20: 5542.24 | X20: 3
B21: Negative length | negative_length - 1 | C21: 5565.36 | D21: 113.07333 | E21: 5561.1916 | F21: 5569.5284 | G21: 558.08422 | H21: 1627.276 | I21: 542.27113 | J21: 573.89731 | K21: 319.74 | L21: 1312858.9 | M21: -129.41381 | N21: 768.89381 | O21: 302.5616 | P21: 1139032.7 | Q21: -115.80227 | R21: 720.92547 | V21: Negative length | negative_length - 1 | W21: 5565.36 | X21: 3
... B29: Итогово | C29: 123737.88 | D29: 3759.2767 | E29: 123713.85 | F29: 123761.91 | G29: 559.50612 | H29: 934.22783 | I29: 547.52458 | J29: 571.48765 | K29: 404.4248 | L29: 1056190 | M29: 1.5620673 | N29: 807.28753 | O29: 167.076 | P29: 87999.121 | Q29: 50.790588 | R29: 283.36141 | V29: Итогово | W29: 123737.88 | X29: 0
A30: 3 | B30: Add a new pet to existing owner | add - 1 | C30: 929 | D30: 851.16667 | E30: 917.56349 | F30: 940.43651 | G30: 613.12875 | H30: 96.85725 | I30: 609.27084 | J30: 616.98666 | K30: 425.4516 | L30: 1151.3526 | M30: 412.15042 | N30: 438.75278 | O30: 255.0468 | P30: 4781.6594 | Q30: 227.94018 | R30: 282.15342 | V30: Add a new pet to existing owner | add - 1 | W30: 929 | X30: 3
B31: Add a visit to a pet | add - 1 | C31: 851.96 | D31: 258.87333 | E31: 845.6529 | F31: 858.2671 | G31: 614.61703 | H31: 56.339804 | I31: 611.67469 | J31: 617.55938 | K31: 406.1352 | L31: 2003.4743 | M31: 388.58921 | N31: 423.68119 | O31: 189.1216 | P31: 7851.5214 | Q31: 154.38695 | R31: 223.85625 | V31: Add a visit to a pet | add - 1 | W31: 851.96 | X31: 3
B32: Add multiple visits - Checkup 1 | checkup1 - 1 | C32: 579.76 | D32: 306.69 | E32: 572.89507 | F32: 586.62493 | G32: 616.07187 | H32: 1472.9707 | I32: 601.02719 | J32: 631.11656 | K32: 606.0112 | L32: 21092.977 | M32: 549.07939 | N32: 662.94301 | O32: 312.6196 | P32: 26599.277 | Q32: 248.6872 | R32: 376.552 | V32: Add multiple visits - Checkup 1 | checkup1 - 1 | W32: 579.76 | X32: 3
B33: Add multiple visits - Checkup 2 | checkup2 - 1 | C33: 576.36 | D33: 258.24 | E33: 570.06062 | F33: 582.65938 | G33: 612.10797 | H33: 48.354454 | I33: 609.3821 | J33: 614.83383 | K33: 579.3508 | L33: 2997.5506 | M33: 557.88884 | N33: 600.81276 | O33: 258.528 | P33: 13985.301 | Q33: 212.17029 | R33: 304.88571 | V33: Add multiple visits - Checkup 2 | checkup2 - 1 | W33: 576.36 | X33: 3
B34: Birth date in future is rejected | future - 1 | C34: 883.52 | D34: 335.26 | E34: 876.34244 | F34: 890.69756 | G34: 612.13641 | H34: 60.091562 | I34: 609.09767 | J34: 615.17514 | K34: 423.6468 | L34: 2730.4986 | M34: 403.16316 | N34: 444.13044 | O34: 228.2668 | P34: 7446.6742 | Q34: 194.43951 | R34: 262.09409 | V34: Birth date in future is rejected | future - 1 | W34: 883.52 | X34: 3
B35: Create new owner with valid data | valid - 1 | C35: 1611.16 | D35: 38674.057 | E35: 1534.0704 | F35: 1688.2496 | G35: 614.46453 | H35: 50.528164 | I35: 611.67807 | J35: 617.25099 | K35: 289.998 | L35: 571.61104 | M35: 280.62591 | N35: 299.37009 | O35: 189.9392 | P35: 3012.289 | Q35: 168.42455 | R35: 211.45385 | V35: Create new owner with valid data | valid - 1 | W35: 1611.16 | X35: 3
B36: Duplicate pet name validation | duplicate - 1 | C36: 852.76 | D36: 392.19 | E36: 844.99692 | F36: 860.52308 | G36: 611.03 | H36: 107.26924 | I36: 606.97002 | J36: 615.08998 | K36: 431.9564 | L36: 2732.5531 | M36: 411.46506 | N36: 452.44774 | O36: 225.0484 | P36: 9615.3307 | Q36: 186.60975 | R36: 263.48705 | V36: Duplicate pet name validation | duplicate - 1 | W36: 852.76 | X36: 3
B37: Edit owner address successfully | edit - 1 | C37: 645.72 | D37: 1682.21 | E37: 629.64222 | F37: 661.79778 | G37: 622.91234 | H37: 1535.8047 | I37: 607.55012 | J37: 638.27457 | K37: 4625.0536 | L37: 3.8048501e+08 | M37: -3021.3082 | N37: 12271.415 | O37: 1345.3084 | P37: 18794544 | Q37: -354.11646 | R37: 3044.7333 | V37: Edit owner address successfully | edit - 1 | W37: 645.72 | X37: 3
B38: Edit pet name successfully | edit - 1 | C38: 574.4 | D38: 209.83333 | E38: 568.72163 | F38: 580.07837 | G38: 612.43562 | H38: 43.941473 | I38: 609.83712 | J38: 615.03413 | K38: 660.0956 | L38: 7381.2948 | M38: 626.41713 | N38: 693.77407 | O38: 415.6908 | P38: 18704.19 | Q38: 362.0796 | R38: 469.302 | V38: Edit pet name successfully | edit - 1 | W38: 574.4 | X38: 2
B39: Find owners by last name multiple results | multiple - 1 | C39: 525.8 | D39: 753.41667 | E39: 515.04021 | F39: 536.55979 | G39: 610.24422 | H39: 109.7613 | I39: 606.13735 | J39: 614.35109 | K39: 882.098 | L39: 5605.6507 | M39: 852.74861 | N39: 911.44739 | O39: 534.0468 | P39: 28449.881 | Q39: 467.9278 | R39: 600.1658 | V39: Find owners by last name multiple results | multiple - 1 | W39: 525.8 | X39: 2
B40: Find owners by last name single result redirects | single - 1 | C40: 568.04 | D40: 554.62333 | E40: 558.80823 | F40: 577.27177 | G40: 615.56672 | H40: 78.997236 | I40: 612.08261 | J40: 619.05083 | K40: 809.172 | L40: 7111.606 | M40: 776.11451 | N40: 842.22949 | O40: 505.972 | P40: 18063.594 | Q40: 453.28686 | R40: 558.65714 | V40: Find owners by last name single result redirects | single - 1 | W40: 568.04 | X40: 2
B41: Find owners no results | none - 1 | C41: 539.76 | D41: 379.94 | E41: 532.11912 | F41: 547.40088 | G41: 616.05469 | H41: 16.067406 | I41: 614.48339 | J41: 617.62599 | K41: 852.71 | L41: 8028.6469 | M41: 817.58573 | N41: 887.83427 | O41: 586.044 | P41: 17927.203 | Q41: 533.55814 | R41: 638.52986 | V41: Find owners no results | none - 1 | W41: 539.76 | X41: 2
B42: Non-existent owner | non_existent - 1 | C42: 1606.28 | D42: 48411993 | E42: -1121.2061 | F42: 4333.7661 | G42: 532.25344 | H42: 1442.3505 | I42: 517.36595 | J42: 547.14093 | K42: 1242.038 | L42: 93693.758 | M42: 1122.049 | N42: 1362.027 | O42: 486.5432 | P42: 43754.866 | Q42: 404.54596 | R42: 568.54044 | V42: Non-existent owner | non_existent - 1 | W42: 1606.28 | X42: 1
... B52: Visits appear on owner details page | history - 1 | C52: 197.68 | D52: 91.976667 | E52: 193.92054 | F52: 201.43946 | G52: 608.43281 | H52: 110.71858 | I52: 604.30808 | J52: 612.55755 | K52: 1719.7572 | L52: 17435.815 | M52: 1667.9957 | N52: 1771.5187 | O52: 991.8368 | P52: 130198.04 | Q52: 850.39157 | R52: 1133.282 | V52: Visits appear on owner details page | history - 1 | W52: 197.68 | X52: 1
B53: Итогово | C53: 18909.16 | D53: 47883410 | E53: 16196.605 | F53: 21621.715 | G53: 602.89999 | H53: 15.842873 | I53: 601.33971 | J53: 604.46027 | K53: 825.3576 | L53: 724819.34 | M53: 491.62322 | N53: 1159.092 | O53: 390.8168 | P53: 34383.906 | Q53: 318.12864 | R53: 463.50496 | V53: Итогово | W53: 18909.16
A56: № проекта | B56: Название теста | C56: Длительность_ДИ | D56: ОЗУ_ДИ | E56: CPU_User_ДИ | F56: СPU_System_ДИ | J56: Среднее по всем проектам
A57: 1 | B57: Standard user logs in | standard_user_login - 1 | C57: =C5-E5 -> 112.22154 | D57: =G5-I5 -> 7.53622 | E57: =K5-M5 -> 23.116355 | F57: =O5-Q5 -> 32.562161 | J57: длительность | K57: =AVERAGE(C8,C29,C53) -> 49546.56
B58: Authorized user checks total item price | check_two_items - 1 | C58: =C6-E6 -> 50.176628 | D58: =G6-I6 -> 3.6956708 | E58: =K6-M6 -> 11.786517 | F58: =O6-Q6 -> 29.400902 | J58: Дисперсия_дл | K58: =VARP(C8,C29,C53) -> 2.7799821e+09
B59: Add 5 different items to the cart | add_five_items - 1 | C59: =C7-E7 -> 90.409971 | D59: =G7-I7 -> 4.6699162 | E59: =K7-M7 -> 10.558672 | F59: =O7-Q7 -> 22.866006 | J59: ДИ_дл | K59: =SQRT(K58)/SQRT(3)*3.182 -> 96863.586
...

Sheet Количество строк
A1: Файлы | B1: Витрина онлайн - магазина | C1: Petclinic | D1: Конверация
A2: GhApproxFeature | B2: =29 -> 29 | C2: =29+7+53+43+9 -> 141 | D2: =6+7+14+7+29 -> 63
A3: GhFeature | B3: =11+18+34 -> 63 | C3: 162 | D3: 81
A4: ConcFeature | B4: =24+37+44 -> 105 | C4: 228 | D4: 192
A5: GhApproxDev | B5: 85 | C5: 77 | D5: 54
A6: GhDev | B6: 163 | C6: 150 | D6: 101
A7: ConcDev | B7: 0 | C7: 0 | D7: 0

Sheet Эксперемент по прогреву
A1: Эксперимент по прогреву - GherkinApprox
A3: Прогон | B3: Килограммы в граммы | C3: Конвертация длины (5) | D3: Конвертация температуры с проверкой значений | E3: Проверка ошибок ввода | F3: Проверка истории при конвертации | G3: Несколько конвертаций | H3: Очистка истории | I3: Общая
A4: 1 | B4: 3143 | C4: 1281 | D4: 843 | E4: 1241 | F4: 811 | G4: 823 | H4: 693 | I4: =SUM(B4:H4) -> 8835
A5: 2 | B5: 2086 | C5: 1237 | D5: 845 | E5: 1247 | F5: 941 | G5: 852 | H5: 731 | I5: =SUM(B5:H5) -> 7939
A6: 3 | B6: 2123 | C6: 1255 | D6: 896 | E6: 1246 | F6: 835 | G6: 903 | H6: 1142 | I6: =SUM(B6:H6) -> 8400
A7: 4 | B7: 2125 | C7: 1239 | D7: 852 | E7: 1253 | F7: 817 | G7: 854 | H7: 710 | I7: =SUM(B7:H7) -> 7850
A8: 5 | B8: 2090 | C8: 1268 | D8: 844 | E8: 1241 | F8: 867 | G8: 841 | H8: 711 | I8: =SUM(B8:H8) -> 7862
A9: 6 | B9: 2161 | C9: 1276 | D9: 884 | E9: 1307 | F9: 785 | G9: 841 | H9: 710 | I9: =SUM(B9:H9) -> 7964
A10: 7 | B10: 9458 | C10: 1325 | D10: 836 | E10: 1248 | F10: 828 | G10: 853 | H10: 719 | I10: =SUM(B10:H10) -> 15267
A11: 8 | B11: 2103 | C11: 1267 | D11: 847 | E11: 1249 | F11: 820 | G11: 888 | H11: 707 | I11: =SUM(B11:H11) -> 7881
A12: 9 | B12: 2114 | C12: 1263 | D12: 833 | E12: 1241 | F12: 789 | G12: 845 | H12: 699 | I12: =SUM(B12:H12) -> 7784
A13: 10 | B13: 2254 | C13: 1244 | D13: 1747 | E13: 1218 | F13: 789 | G13: 800 | H13: 710 | I13: =SUM(B13:H13) -> 8762
A14: 11 | B14: 2023 | C14: 1857 | D14: 852 | E14: 1321 | F14: 847 | G14: 862 | H14: 786 | I14: =SUM(B14:H14) -> 8548
A15: 12 | B15: 2182 | C15: 1290 | D15: 975 | E15: 1325 | F15: 834 | G15: 851 | H15: 720 | I15: =SUM(B15:H15) -> 8177
... A28: 25 | B28: 2103 | C28: 1520 | D28: 899 | E28: 1237 | F28: 825 | G28: 843 | H28: 725 | I28: =SUM(B28:H28) -> 8152
A29: Медиана | B29: =MEDIAN(B4:B28) -> 2123 | C29: =MEDIAN(C4:C28) -> 1267 | D29: =MEDIAN(D4:D28) -> 847 | E29: =MEDIAN(E4:E28) -> 1246 | F29: =MEDIAN(F4:F28) -> 817 | G29: =MEDIAN(G4:G28) -> 848 | H29: =MEDIAN(H4:H28) -> 710 | I29: =MEDIAN(I4:I28) -> 8030
A30: Медиана без аномалий | B30: =MEDIAN(B5:B9,B11:B28) -> 2122 | C30: =MEDIAN(C4:C13,C15:C20,C22:C24,C26:C27) -> 1263 | D30: =MEDIAN(D16:D28,D14,D4:D12) -> 847 | E30: =MEDIAN(E4:E21,E23:E25,E27:E28) -> 1241 | F30: =MEDIAN(F4,F6:F15,F17:F22,F24:F25,F27:F28) -> 815 | G30: =MEDIAN(G4:G5,G7:G10,G12:G13,G15:G25,G28) -> 843 | H30: =MEDIAN(H4:H5,H7:H13,H15:H16,H18:H23,H25:H28) -> 710 | I30: =MEDIAN(I11:I28,I4:I9) -> 8021.5
A32: Отклонение мед, % | B32: =(B29-B30)/B30*100 -> 0.047125353 | C32: =(C29-C30)/C30*100 -> 0.31670625 | D32: =(D29-D30)/D30*100 -> 0 | E32: =(E29-E30)/E30*100 -> 0.40290089 | F32: =(F29-F30)/F30*100 -> 0.24539877 | G32: =(G29-G30)/G30*100 -> 0.59311981 | H32: =(H29-H30)/H30*100 -> 0 | I32: =(I29-I30)/I30*100 -> 0.10596522
A33: Среднее | B33: =AVERAGE(B4:B28) -> 2460.36 | C33: =AVERAGE(C4:C28) -> 1328.4 | D33: =AVERAGE(D4:D28) -> 891.32 | E33: =AVERAGE(E4:E28) -> 1301.92 | F33: =AVERAGE(F4:F28) -> 842.52 | G33: =AVERAGE(G4:G28) -> 850.48 | H33: =AVERAGE(H4:H28) -> 737.92 | I33: =AVERAGE(I4:I28) -> 8412.92
A34: Дисперсия | B34: =VARP(B4:B28) -> 2083374.3 | C34: =VARP(C4:C28) -> 22858.96 | D34: =VARP(D4:D28) -> 31421.258 | E34: =VARP(E4:E28) -> 31825.594 | F34: =VARP(F4:F28) -> 6462.4896 | G34: =VARP(G4:G28) -> 467.4496 | H34: =VARP(H4:H28) -> 7921.8336 | I34: =VARP(I4:I28) -> 2045994.6
A35: Дов. интервал | B35: =SQRT(B34)/SQRT(25)*1.96 -> 565.80883 | C35: =SQRT(C34)/SQRT(25)*1.96 -> 59.267185 | D35: =SQRT(D34)/SQRT(25)*1.96 -> 69.486086 | E35: =SQRT(E34)/SQRT(25)*1.96 -> 69.931738 | F35: =SQRT(F34)/SQRT(25)*1.96 -> 31.512728 | G35: =SQRT(G34)/SQRT(25)*1.96 -> 8.4752685 | H35: =SQRT(H34)/SQRT(25)*1.96 -> 34.889836 | I35: =SQRT(I34)/SQRT(25)*1.96 -> 560.71
A36: Верхняя | B36: =B33+B35 -> 3026.1688 | C36: =C33+C35 -> 1387.6672 | D36: =D33+D35 -> 960.80609 | E36: =E33+E35 -> 1371.8517 | F36: =F33+F35 -> 874.03273 | G36: =G33+G35 -> 858.95527 | H36: =H33+H35 -> 772.80984 | I36: =I33+I35 -> 8973.63
A37: Среднее без аномалий | B37: =AVERAGE(B5:B9,B11:B28) -> 2126.4348 | C37: =AVERAGE(C4:C13,C15:C20,C22:C24,C26:C27) -> 1267.4286 | D37: =AVERAGE(D16:D28,D14,D4:D12) -> 850.47826 | E37: =AVERAGE(E4:E21,E23:E25,E27:E28) -> 1251.5652 | F37: =AVERAGE(F4,F6:F15,F17:F22,F24:F25,F27:F28) -> 814.85714 | G37: =AVERAGE(G4:G5,G7:G10,G12:G13,G15:G25,G28) -> 842.1 | H37: =AVERAGE(H4:H5,H7:H13,H15:H16,H18:H23,H25:H28) -> 709.28571 | I37: =AVERAGE(I11:I28,I4:I9) -> 8127.3333
A39: дисперсия без аномалий | B39: =VAR(B5:B9,B11:B28) -> 3943.4387 | C39: =VARP(C4:C13,C15:C20,C22:C24,C26:C27) -> 952.43537 | D39: =VARP(D16:D28,D14,D4:D12) -> 346.77127 | E39: =VARP(E4:E21,E23:E25,E27:E28) -> 781.81096 | F39: =VARP(F4,F6:F15,F17:F22,F24:F25,F27:F28) -> 410.59864 | G39: =VARP(G4:G5,G7:G10,G12:G13,G15:G25,G28) -> 171.89 | H39: =VARP(H4:H5,H7:H13,H15:H16,H18:H23,H25:H28) -> 88.870748 | I39: =VARP(I11:I28,I4:I9) -> 92250.722
A41: Отклонение ср, % | B41: =(B33-B37)/B37*100 -> 15.703525 | C41: =(C33-C37)/C37*100 -> 4.8106402 | D41: =(D33-D37)/D37*100 -> 4.8022085 | E41: =(E33-E37)/E37*100 -> 4.0233447 | F41: =(F33-F37)/F37*100 -> 3.3948107 | G41: =(G33-G37)/G37*100 -> 0.99513122 | H41: =(H33-H37)/H37*100 -> 4.0370594 | I41: =(I33-I37)/I37*100 -> 3.5139037
A43: Эксперимент по прогреву - Cucumber
A45: Прогон | B45: Конвертация массы | C45: Конвертация длины | D45: Конвертация температуры | E45: Проверка ошибок ввода | F45: Результат добавляется в историю | G45: Несколько конвертаций | H45: Очистка истории | I45: Ошибка не попадает в историю | J45: Общая
A46: 1 | B46: 1384 | C46: 2098 | D46: 1253 | E46: 2988 | F46: 403 | G46: 610 | H46: 966 | I46: 415 | J46: =SUM(B46:I46) -> 10117
A47: 2 | B47: 1115 | C47: 2113 | D47: 1237 | E47: 3853 | F47: 606 | G47: 617 | H47: 940 | I47: 419 | J47: =SUM(B47:I47) -> 10900
A48: 3 | B48: 1109 | C48: 2141 | D48: 1276 | E48: 3202 | F48: 425 | G48: 667 | H48: 975 | I48: 415 | J48: =SUM(B48:I48) -> 10210
A49: 4 | B49: 1081 | C49: 2146 | D49: 1269 | E49: 3208 | F49: 390 | G49: 632 | H49: 950 | I49: 433 | J49: =SUM(B49:I49) -> 10109
A50: 5 | B50: 1141 | C50: 2172 | D50: 1261 | E50: 3103 | F50: 433 | G50: 584 | H50: 955 | I50: 425 | J50: =SUM(B50:I50) -> 10074
A51: 6 | B51: 1078 | C51: 2280 | D51: 1344 | E51: 3472 | F51: 435 | G51: 633 | H51: 986 | I51: 472 | J51: =SUM(B51:I51) -> 10700
A52: 7 | B52: 1098 | C52: 2110 | D52: 1498 | E52: 3136 | F52: 421 | G52: 616 | H52: 948 | I52: 426 | J52: =SUM(B52:I52) -> 10253
A53: 8 | B53: 1065 | C53: 2146 | D53: 1484 | E53: 3007 | F53: 404 | G53: 624 | H53: 923 | I53: 470 | J53: =SUM(B53:I53) -> 10123
A54: 9 | B54: 1071 | C54: 2186 | D54: 1529 | E54: 3012 | F54: 440 | G54: 631 | H54: 967 | I54: 404 | J54: =SUM(B54:I54) -> 10240
A55: 10 | B55: 1140 | C55: 2396 | D55: 1396 | E55: 3024 | F55: 455 | G55: 620 | H55: 996 | I55: 419 | J55: =SUM(B55:I55) -> 10446
A56: 11 | B56: 1209 | C56: 3038 | D56: 1337 | E56: 3066 | F56: 437 | G56: 649 | H56: 945 | I56: 418 | J56: =SUM(B56:I56) -> 11099
A57: 12 | B57: 1174 | C57: 2131 | D57: 1341 | E57: 2969 | F57: 463 | G57: 714 | H57: 971 | I57: 437 | J57: =SUM(B57:I57) -> 10200
... A70: 25 | B70: 1076 | C70: 2199 | D70: 1277 | E70: 3124 | F70: 423 | G70: 630 | H70: 1112 | I70: 435 | J70: =SUM(B70:I70) -> 10276
...
